<?xml version="1.0" ?>
<robot name="sevenbot">
  <!-- Gazebo Plugin -->
  <gazebo>
    <plugin filename="libgazebo_ros_control.so" name="ros_control">
      <robotNamespace>sevenbot</robotNamespace>
      <controlPeriod>0.001</controlPeriod>
    </plugin>
  </gazebo>

  <joint name="sevenbot_base_joint" type="fixed">
    <parent link="world"/>
    <child link="sevenbot_base_link"/>
  </joint>
  <link name="world"/>
  <link name="sevenbot_base_link">
    <visual>
      <origin rpy="0 0 0" xyz="-0.035 0 0.025"/>
      <geometry>
        <box size="0.165 0.085 0.05"/>
      </geometry>
      <material name="silver">
        <color rgba=".8 .8 .8 1"/>
      </material>
    </visual>
  </link>

  <!-- base->l1 -->
  <joint name="j1" type="revolute">
    <axis xyz="0 0 1"/>
    <origin rpy="0 0 0" xyz="0 0 0.05"/>
    <parent link="sevenbot_base_link"/>
    <child link="l1"/>
    <dynamics damping="0.01" friction="0.0"/>
    <limit effort="100" lower="-1.57" upper="1.57" velocity="100.0"/>
  </joint>
  <transmission name="trans_j1">
    <type>transmission_interface/SimpleTransmission</type>
    <joint name="j1"/>
    <actuator name="motor_j1">
      <hardwareInterface>EffortJointInterface</hardwareInterface>
      <mechanicalReduction>1</mechanicalReduction>
    </actuator>
  </transmission>
  <link name="l1">
    <visual>
      <origin rpy="0 0 0" xyz="0 0 0.015"/>
      <geometry>
        <!-- <box size="0.08 0.065 0.1"/> -->
        <cylinder length="0.03" radius="0.03"/>
      </geometry>
      <material name="silver"/>
    </visual>
    <visual>
      <origin rpy="0 0 0" xyz="0 0 0.055"/>
      <geometry>
        <!-- <box size="0.08 0.065 0.1"/> -->
        <cylinder length="0.05" radius="0.01"/>
      </geometry>
      <material name="silver"/>
    </visual>
  </link>

  <!-- l1->l2 -->
  <joint name="j2" type="revolute">
    <axis xyz="0 -1 0"/>
    <!-- <origin rpy="0 2 0" xyz="0.03 0 0.075"/> -->
     <origin rpy="0 1.57 0" xyz="0 0 0.08"/>
    <parent link="l1"/>
    <child link="l2"/>
    <dynamics damping="0.01" friction="-1.0"/>
    <limit effort="100" lower="0" upper="1.57" velocity="100.0"/>
  </joint>
  <transmission name="trans_j2">
    <type>transmission_interface/SimpleTransmission</type>
    <joint name="j2"/>
    <actuator name="motor_j2">
      <hardwareInterface>EffortJointInterface</hardwareInterface>
      <mechanicalReduction>1</mechanicalReduction>
    </actuator>
  </transmission>
  <link name="l2">
    <inertial>
      <origin rpy="0 0 0" xyz="0 0 0"/>
      <mass value="0.1"/>
      <inertia ixx="0.1" ixy="0" ixz="0" iyy="0.1" iyz="0" izz="0.1"/>
    </inertial>
    <visual>
      <origin rpy="0 0 0" xyz="-0.06 0 0"/>
      <geometry>
        <box size="0.12 0.03 0.02"/>
      </geometry>
      <material name="silver"/>
    </visual>
  </link>

  <!--l2->l2m -->
  <joint name="j2m" type="revolute">
    <axis xyz="0 -1 0"/>
    <origin rpy="0 0 0" xyz="-0.12 0 0"/>
    <parent link="l2"/>
    <child link="l2m"/>
    <limit effort="100" lower="0" upper="1.57" velocity="100.0"/>
    <mimic joint="j2" multiplier="-1"/>
  </joint>
  <transmission name="trans_j2m">
    <type>transmission_interface/SimpleTransmission</type>
    <joint name="j2m"/>
    <actuator name="motor_j2m">
      <hardwareInterface>EffortJointInterface</hardwareInterface>
      <mechanicalReduction>1</mechanicalReduction>
    </actuator>
  </transmission>
  <link name="l2m">
    <interial>
      <origin rpy="0 0 0" xyz="0 0 0"/>
      <mass value="0.1"/>
      <interia ixx="0.1" ixy="0" ixz="0" iyy="0.1" iyz="0" izz="0.1"/>
    </interial>
  </link>

  <!-- l2m->l3 -->
  <joint name="j3" type="revolute">
    <axis xyz="0 1 0"/>
    <origin rpy="0 0.43644 0" xyz="0 0 0"/> <!--25 dgree-->
    <parent link="l2m"/>
    <child link="l3"/>
    <dynamics damping="0.01" friction="0.0"/>
    <limit effort="100" lower="0" upper="3.14" velocity="100.0"/>
  </joint>
  <transmission name="trans_j3">
    <type>transmission_interface/SimpleTransmission</type>
    <joint name="j3"/>
    <actuator name="motor_j3">
      <hardwareInterface>EffortJointInterface</hardwareInterface>
      <mechanicalReduction>1</mechanicalReduction>
    </actuator>
  </transmission>
  <link name="l3">
    <visual>
      <origin rpy="0 0 0" xyz="-0.025 0 0"/>
      <geometry>
        <box size="0.04 0.045 0.06"/>
      </geometry>
      <material name="silver"/>
    </visual>
  </link>

  <!-- l3->l4 -->
  <joint name="j4" type="revolute">
    <axis xyz="0 0 1"/>
    <origin rpy="0 0 0" xyz="-0.025 0 0"/>
    <parent link="l3"/>
    <child link="l4"/>
    <dynamics damping="0.01" friction="0.0"/>
    <limit effort="100" lower="-1.57" upper="1.57" velocity="100.0"/>
  </joint>
  <transmission name="trans_j4">
    <type>transmission_interface/SimpleTransmission</type>
    <joint name="j4"/>
    <actuator name="motor_j4">
      <hardwareInterface>EffortJointInterface</hardwareInterface>
      <mechanicalReduction>1</mechanicalReduction>
    </actuator>
  </transmission>
  <link name="l4">
    <visual>
      <origin rpy="0 0 0" xyz="0 0 0.1"/>
      <geometry>
        <cylinder length="0.2" radius="0.01"/>
      </geometry>
      <material name="silver"/>
    </visual>
  </link>


  <joint name="j5" type="revolute">
    <axis xyz="0 1 0"/>
    <origin rpy="0 0 0" xyz="0 0 0.21"/>
    <parent link="l4"/>
    <child link="gripper"/>
    <dynamics damping="0.01" friction="0.0"/>
    <limit effort="100" lower="-1.57" upper="1.57" velocity="100.0"/>
  </joint>
  <transmission name="trans_j5">
    <type>transmission_interface/SimpleTransmission</type>
    <joint name="j5"/>
    <actuator name="motor_j5">
      <hardwareInterface>EffortJointInterface</hardwareInterface>
      <mechanicalReduction>1</mechanicalReduction>
    </actuator>
  </transmission>

  <link name="gripper">
    <visual>
      <origin rpy="0 0 0" xyz="0 0 0"/>
      <geometry>
        <box size="0.015 0.015 0.015"/>
      </geometry>
      <material name="silver"/>
    </visual>

    <visual>
      <origin rpy="0 0 0" xyz="0 0 0.0075"/>
      <geometry>
        <cylinder length="0.003" radius="0.015"/>
      </geometry>
      <material name="silver"/>
    </visual>
  </link>

  <joint name="j6" type="revolute">
    <axis xyz="0 0 1"/>
    <origin rpy="0 0 0" xyz="0 0 0.2075"/>
    <parent link="l4"/>
    <child link="gripper"/>
    <dynamics damping="0.01" friction="0.0"/>
    <limit effort="100" lower="-1.57" upper="1.57" velocity="100.0"/>
  </joint>
  <transmission name="trans_j6">
    <type>transmission_interface/SimpleTransmission</type>
    <joint name="j6"/>
    <actuator name="motor_j6">
      <hardwareInterface>EffortJointInterface</hardwareInterface>
      <mechanicalReduction>1</mechanicalReduction>
    </actuator>
  </transmission>

  <!--
  <link name="l5">
    <inertial>
      <origin rpy="0 0 0" xyz="0 0 0.5"/>
      <mass value="0.1"/>
      <inertia ixx="0.1" ixy="0" ixz="0" iyy="0.1" iyz="0" izz="0.1"/>
    </inertial>
    <visual>
      <origin rpy="0 0 0" xyz="0.01 0 0"/>
      <geometry>
        <box size="0.04 0.025 0.015"/>
      </geometry>
      <material name="silver"/>
    </visual>
  </link>
  <link name="l6">
    <inertial>
      <origin rpy="0 0 0" xyz="0 0 0.5"/>
      <mass value="0.1"/>
      <inertia ixx="0.1" ixy="0" ixz="0" iyy="0.1" iyz="0" izz="0.1"/>
    </inertial>
    <visual>
      <origin rpy="0 0 0" xyz="0 0 0"/>
      <geometry>
        <cylinder length="0.003" radius="0.015"/>
      </geometry>
      <material name="silver"/>
    </visual>
  </link>
  -->
<!--
  <link name="l7">
    <inertial>
      <origin rpy="0 0 0" xyz="0 0 0.5"/>
      <mass value="0.1"/>
      <inertia ixx="0.1" ixy="0" ixz="0" iyy="0.1" iyz="0" izz="0.1"/>
    </inertial>
    <visual>
      <origin rpy="0 0 0" xyz="0.5 0 0.5"/>
      <geometry>
        <box size="0.1 0.1 0.1"/>
      </geometry>
    </visual>
  </link>
  -->

  <!--j2 : l1--l2 -->



  <!--
  <joint name="j7" type="revolute">
    <axis xyz="1 0 0"/>
    <origin rpy="0 0 0" xyz="0 0 0.1"/>
    <parent link="l6"/>
    <child link="l7"/>
    <dynamics damping="0.01" friction="0.0"/>
    <limit effort="100" lower="-1.57" upper="1.57" velocity="100.0"/>
  </joint>
  <transmission name="trans_j7">
    <type>transmission_interface/SimpleTransmission</type>
    <joint name="j7"/>
    <actuator name="motor_j7">
      <hardwareInterface>EffortJointInterface</hardwareInterface>
      <mechanicalReduction>1</mechanicalReduction>
    </actuator>
  </transmission>
  -->
</robot>
